<?xml version="1.0"?>
<robot xmlns:xacro="http://wiki.ros.org/xacro" >

  <xacro:macro name="mecanum">
  <xacro:property name="base_length" value="1.15"/>
  <xacro:property name="base_width" value="0.67"/>
  <xacro:property name="base_height" value="0.451"/>
  <xacro:property name="base_offset_x" value="-0.07"/>
  
  <link name="world"/>

  <joint name="x_dir_joint" type="prismatic">
    <parent link="world"/>
    <child link="x_dir_link"/>
    <origin rpy="0.0 0.0 0.0" xyz="0.0 0.0 0.0"/>
    <axis xyz="1 0 0"/>
    <limit effort="100" lower="-100" upper="100" velocity="50"/>
    <dynamics damping="0.0" friction="0.0"/>
  </joint>

  <link name="x_dir_link">
    <inertial>
      <mass value="0.1"/>
      <origin xyz="0 0 0" rpy="0 0 0"/>
      <inertia ixx="1.0" ixy="0.0" ixz="0.0" iyy="1.0" iyz="0.0" izz="1.0"/>
    </inertial>
  </link>

  <joint name="y_dir_joint" type="prismatic">
    <parent link="x_dir_link"/>
    <child link="y_dir_link"/>
    <origin rpy="0.0 0.0 0.0" xyz="0.0 0.0 0.0"/>
    <axis xyz="0 1 0"/>
    <limit effort="100" lower="-100" upper="100" velocity="50"/>
    <dynamics damping="0.0" friction="0.0"/>
  </joint>

  <link name="y_dir_link">
    <inertial>
      <mass value="0.1"/>
      <origin xyz="0 0 0" rpy="0 0 0"/>
      <inertia ixx="1.0" ixy="0.0" ixz="0.0" iyy="1.0" iyz="0.0" izz="1.0"/>
    </inertial>
  </link>

  <joint name="z_dir_joint" type="continuous">
    <parent link="y_dir_link"/>
    <child link="z_dir_link"/>
    <origin rpy="0.0 0.0 0.0" xyz="0.0 0.0 0.0"/>
    <axis xyz="0 0 1"/>
    <limit effort="100" velocity="50"/>
    <dynamics damping="0.0" friction="0.0"/>
  </joint>

  <link name="z_dir_link">
    <inertial>
      <mass value="0.1"/>
      <origin xyz="0 0 0" rpy="0 0 0"/>
      <inertia ixx="1.0" ixy="0.0" ixz="0.0" iyy="1.0" iyz="0.0" izz="1.0"/>
    </inertial>
    <visual>
      <origin xyz="${base_offset_x} 0 ${base_height}" rpy="0 0 0"/>
      <geometry>
         <mesh filename="package://mobile_manipulator_sim/meshes/mec.dae" scale="1 1 1"/> 
        <!-- <box size="${base_length} ${base_width} ${base_height}"/>   -->
        <!-- <box size="0.1 0.1 0.1"/> -->
      </geometry>
      <material name="blue">  
        <color rgba="0.3 0.5 0.6 1"/>  
      </material> 
    </visual>
    <!-- <collision>
      <origin xyz="0 0 0" rpy="0 0 0"/>
      <geometry>
        <box size="0.001 0.001 0.001"/>
      </geometry>
    </collision> -->
  </link>
  
 
  <transmission name="x_dir_trans">
    <type>transmission_interface/SimpleTransmission</type>
    <joint name="x_dir_joint">
      <hardwareInterface>hardware_interface/VelocityJointInterface</hardwareInterface>
    </joint>
    <actuator name="x_dir_motor">
      <mechanicalReduction>1</mechanicalReduction>
    </actuator>
  </transmission>

  <gazebo reference="x_dir_link">
    <selfCollide>false</selfCollide>
    <turnGravityOff>true</turnGravityOff>
  </gazebo>

  <transmission name="y_dir_trans">
    <type>transmission_interface/SimpleTransmission</type>
    <joint name="y_dir_joint">
      <hardwareInterface>hardware_interface/VelocityJointInterface</hardwareInterface>
    </joint>
    <actuator name="y_dir_motor">
      <mechanicalReduction>1</mechanicalReduction>
    </actuator>
  </transmission>

  <gazebo reference="y_dir_link">
    <selfCollide>false</selfCollide>
    <turnGravityOff>true</turnGravityOff>
  </gazebo>

    <transmission name="z_dir_trans">
    <type>transmission_interface/SimpleTransmission</type>
    <joint name="z_dir_joint">
      <hardwareInterface>hardware_interface/VelocityJointInterface</hardwareInterface>
    </joint>
    <actuator name="z_dir_motor">
      <mechanicalReduction>1</mechanicalReduction>
    </actuator>
  </transmission>

  <gazebo reference="z_dir_link">
    <selfCollide>false</selfCollide>
    <turnGravityOff>true</turnGravityOff>
  </gazebo>
 
  </xacro:macro>
 
</robot>